{
    "registryname": "simulation_chamber",
    "localizedname": "Supercomputer Simulation Chamber",
    "parts": [
        {
            "x": -1,
            "y": 0,
            "z": 0,
            "elements": [
                "nuclearcraft:fission_block@0"
            ]
        },
        {
            "x": -1,
            "y": 0,
            "z": 1,
            "elements": [
                "modularmachinery:blockcasing@3"
            ]
        },
        {
            "x": 0,
            "y": 0,
            "z": 1,
            "elements": [
                "deepmoblearning:simulation_chamber@1"
            ]
        },
        {
            "x": 1,
            "y": 0,
            "z": 0,
            "elements": [
                "nuclearcraft:fission_block@0"
            ]
        },
        {
            "x": -1,
            "y": 0,
            "z": 2,
            "elements": [
                "nuclearcraft:fission_block@0"
            ]
        },
        {
            "x": 1,
            "y": 0,
            "z": 1,
            "elements": [
                "modularmachinery:blockcasing@3"
            ]
        },
        {
            "x": 0,
            "y": 0,
            "z": 2,
            "elements": [
                "minecraft:glass@0"
            ]
        },
        {
            "x": 1,
            "y": 0,
            "z": 2,
            "elements": [
                "nuclearcraft:fission_block@0"
            ]
        },
        {
            "x": 1,
            "y": -1,
            "z": 0,
            "elements": [
                "nuclearcraft:fission_block@0"
            ]
        },
        {
            "x": 0,
            "y": -1,
            "z": 0,
            "elements": [
                "nuclearcraft:fission_block@0"
            ]
        },
        {
            "x": -1,
            "y": 1,
            "z": 0,
            "elements": [
                "modularmachinery:blockinputbus@0"
            ]
        },
        {
            "x": -1,
            "y": -1,
            "z": 0,
            "elements": [
                "nuclearcraft:fission_block@0"
            ]
        },
        {
            "x": 0,
            "y": 1,
            "z": 0,
            "elements": [
                "nuclearcraft:fission_block@0"
            ]
        },
        {
            "x": -1,
            "y": 1,
            "z": 1,
            "elements": [
                "nuclearcraft:fission_block@0"
            ]
        },
        {
            "x": 0,
            "y": 1,
            "z": 1,
            "elements": [
                "nuclearcraft:fission_block@0"
            ]
        },
        {
            "x": 1,
            "y": 1,
            "z": 0,
            "elements": [
                "modularmachinery:blockinputbus@0"
            ]
        },
        {
            "x": -1,
            "y": 1,
            "z": 2,
            "elements": [
                "nuclearcraft:fission_block@0"
            ]
        },
        {
            "x": 0,
            "y": 1,
            "z": 2,
            "elements": [
                "modularmachinery:blockenergyinputhatch"
            ]
        },
        {
            "x": 1,
            "y": 1,
            "z": 1,
            "elements": [
                "nuclearcraft:fission_block@0"
            ]
        },
        {
            "x": -1,
            "y": -1,
            "z": 1,
            "elements": [
                "nuclearcraft:fission_block@0"
            ]
        },
        {
            "x": 1,
            "y": 1,
            "z": 2,
            "elements": [
                "nuclearcraft:fission_block@0"
            ]
        },
        {
            "x": 0,
            "y": -1,
            "z": 1,
            "elements": [
                "nuclearcraft:fission_block@0"
            ]
        },
        {
            "x": -1,
            "y": -1,
            "z": 2,
            "elements": [
                "nuclearcraft:fission_block@0"
            ]
        },
        {
            "x": 0,
            "y": -1,
            "z": 2,
            "elements": [
                "modularmachinery:blockoutputbus@1"
            ]
        },
        {
            "x": 1,
            "y": -1,
            "z": 1,
            "elements": [
                "nuclearcraft:fission_block@0"
            ]
        },
        {
            "x": 1,
            "y": -1,
            "z": 2,
            "elements": [
                "nuclearcraft:fission_block@0"
            ]
        }
    ],
    "modifiers": [
        {
            "x": -1,
            "y": 0,
            "z": 1,
            "elements": "contenttweaker:upgrade_speed_1",
            "description": "Make this machine run 30% faster! Stacks for each gearbox block replaced.",
            "modifier": {
                "io": "input",
                "target": "duration",
                "operation": 1,
                "multiplier": 0.7
            }
        },
        {
            "x": -1,
            "y": 0,
            "z": 1,
            "elements": "contenttweaker:upgrade_speed_2",
            "description": "Make this machine run 50% faster! Stacks for each gearbox block replaced.",
            "modifier": {
                "io": "input",
                "target": "duration",
                "operation": 1,
                "multiplier": 0.5
            }
        },
        {
            "x": -1,
            "y": 0,
            "z": 1,
            "elements": "contenttweaker:upgrade_speed_3",
            "description": "Make this machine run 75% faster! Stacks for each gearbox block replaced.",
            "modifier": {
                "io": "input",
                "target": "duration",
                "operation": 1,
                "multiplier": 0.25
            }
        },
        {
            "x": -1,
            "y": 0,
            "z": 1,
            "elements": "contenttweaker:upgrade_energy_1",
            "description": "Make this machine run 30% faster! Stacks for each gearbox block replaced.",
            "modifier": {
                "io": "input",
                "target": "energy",
                "operation": 1,
                "multiplier": 0.7
            }
        },
        {
            "x": -1,
            "y": 0,
            "z": 1,
            "elements": "contenttweaker:upgrade_energy_2",
            "description": "Make this machine run 50% faster! Stacks for each gearbox block replaced.",
            "modifier": {
                "io": "input",
                "target": "energy",
                "operation": 1,
                "multiplier": 0.5
            }
        },
        {
            "x": -1,
            "y": 0,
            "z": 1,
            "elements": "contenttweaker:upgrade_energy_3",
            "description": "Make this machine run 75% faster! Stacks for each gearbox block replaced.",
            "modifier": {
                "io": "input",
                "target": "energy",
                "operation": 1,
                "multiplier": 0.25
            }
        },
        {
            "x": 1,
            "y": 0,
            "z": 1,
            "elements": "contenttweaker:upgrade_speed_1",
            "description": "Make this machine run 30% faster! Stacks for each gearbox block replaced.",
            "modifier": {
                "io": "input",
                "target": "duration",
                "operation": 1,
                "multiplier": 0.7
            }
        },
        {
            "x": 1,
            "y": 0,
            "z": 1,
            "elements": "contenttweaker:upgrade_speed_2",
            "description": "Make this machine run 50% faster! Stacks for each gearbox block replaced.",
            "modifier": {
                "io": "input",
                "target": "duration",
                "operation": 1,
                "multiplier": 0.5
            }
        },
        {
            "x": 1,
            "y": 0,
            "z": 1,
            "elements": "contenttweaker:upgrade_speed_3",
            "description": "Make this machine run 75% faster! Stacks for each gearbox block replaced.",
            "modifier": {
                "io": "input",
                "target": "duration",
                "operation": 1,
                "multiplier": 0.25
            }
        },
        {
            "x": 1,
            "y": 0,
            "z": 1,
            "elements": "contenttweaker:upgrade_energy_1",
            "description": "Make this machine run 30% faster! Stacks for each gearbox block replaced.",
            "modifier": {
                "io": "input",
                "target": "energy",
                "operation": 1,
                "multiplier": 0.7
            }
        },
        {
            "x": 1,
            "y": 0,
            "z": 1,
            "elements": "contenttweaker:upgrade_energy_2",
            "description": "Make this machine run 50% faster! Stacks for each gearbox block replaced.",
            "modifier": {
                "io": "input",
                "target": "energy",
                "operation": 1,
                "multiplier": 0.5
            }
        },
        {
            "x": 1,
            "y": 0,
            "z": 1,
            "elements": "contenttweaker:upgrade_energy_3",
            "description": "Make this machine run 75% faster! Stacks for each gearbox block replaced.",
            "modifier": {
                "io": "input",
                "target": "energy",
                "operation": 1,
                "multiplier": 0.25
            }
        }
    ]
}